<?xml version="1.0"?>
<robot xmlns:xacro="http://www.ros.org/wiki/xacro">

    <xacro:macro name="padwq" params="prefix">

        <xacro:property name="deg2rad" value="${pi/180}"/>

        <link name="base_link">
            <inertial>
                <origin rpy="0 0 0" xyz="0 0 0"/>
                <mass value="12"/>
                <inertia ixx="0.0683" ixy="0" ixz="0" iyy="0.1872" iyz="0" izz="0.2322"/>
            </inertial>
            <visual>
                <geometry>
                    <box size="0.283 0.180 0.108"/>
                </geometry>
                <material name="red"/>
            </visual>
            <collision>
                <geometry>
                    <box size="0.283 0.180 0.108"/>
                </geometry>
            </collision>
        </link>

        <!-- Front Left -->

        <joint name="fl_hip_roll" type="revolute">
            <axis xyz="0 0 1"/>
            <parent link="base_link"/>
            <child link="fl_hip_roll_actuator"/>
            <origin rpy="0 1.5708 0" xyz="0.1415 0.07 0"/>
            <limit effort="1000.0" lower="${-30 * deg2rad}" upper="${30 * deg2rad}" velocity="10"/>
            <dynamics damping="1.0" friction="1.0"/>
        </joint>

        <link name="fl_hip_roll_actuator">
            <inertial>
                <mass value="2e-06"/>
                <inertia ixx="1.1e-09" ixy="0" ixz="0" iyy="1.1e-09" iyz="0" izz="1.1e-09"/>
            </inertial>
        </link>

        <joint name="fl_hip_pitch" type="revolute">
            <axis xyz="0 1 0"/>
            <parent link="fl_hip_roll_actuator"/>
            <child link="fl_upper_link"/>
            <origin rpy="0 0 0" xyz="0 0.0835 0.068"/>
            <limit effort="1000.0" lower="${-51 * deg2rad}" upper="${93 * deg2rad}" velocity="10"/>
            <dynamics damping="1.0" friction="1.0"/>
        </joint>

        <link name="fl_upper_link">
            <inertial>
                <origin rpy="0 0 0" xyz="0.11 0 0"/>
                <mass value="0.3"/>
                <inertia ixx="0.000066667" ixy="0" ixz="0" iyy="0.016166667" iyz="0" izz="0.016166667"/>
            </inertial>
            <visual>
                <origin rpy="0 0 0" xyz="0.11 0 0"/>
                <geometry>
                    <box size="0.22 0.04 0.04"/>
                </geometry>
                <material name="blue"/>
            </visual>
            <collision>
                <origin rpy="0 0 0" xyz="0.11 0 0"/>
                <geometry>
                    <box size="0.22 0.04 0.04"/>
                </geometry>
            </collision>
        </link>

        <joint name="fl_knee_pitch" type="revolute">
            <axis xyz="0 1 0"/>
            <parent link="fl_upper_link"/>
            <child link="fl_under_link"/>
            <origin rpy="0 0 0" xyz="0.22 0 0"/>
            <limit effort="1000.0" lower="${7 * deg2rad}" upper="${134 * deg2rad}" velocity="10"/>
            <dynamics damping="1.0" friction="1.0"/>
        </joint>

        <link name="fl_under_link">
            <inertial>
                <origin rpy="0 0 0" xyz="0.11 0 0"/>
                <mass value="0.3"/>
                <inertia ixx="0.000066667" ixy="0" ixz="0" iyy="0.016166667" iyz="0" izz="0.016166667"/>
            </inertial>
            <visual>
                <origin rpy="0 0 0" xyz="0.11 0 0"/>
                <geometry>
                    <box size="0.22 0.04 0.04"/>
                </geometry>
                <material name="blue"/>
            </visual>
            <collision>
                <origin rpy="0 0 0" xyz="0.11 0 0"/>
                <geometry>
                    <box size="0.22 0.04 0.04"/>
                </geometry>
            </collision>
        </link>

        <joint name="fl_foot" type="fixed">
            <axis xyz="0 1 0"/>
            <parent link="fl_under_link"/>
            <child link="fl_foot"/>
            <origin rpy="0 0 0" xyz="0.22 0 0"/>
        </joint>

        <link name="fl_foot">
            <inertial>
                <mass value="2e-06"/>
                <inertia ixx="1.1e-09" ixy="0" ixz="0" iyy="1.1e-09" iyz="0" izz="1.1e-09"/>
            </inertial>
            <visual>
                <origin rpy="0 0 0" xyz="0 0 0"/>
                <geometry>
                    <sphere radius="0.025"/>
                </geometry>
                <material name="white"/>
            </visual>
            <collision>
                <origin rpy="0 0 0" xyz="0 0 0"/>
                <geometry>
                    <sphere radius="0.025"/>
                </geometry>
            </collision>
        </link>

        <!-- Front Right -->

        <joint name="fr_hip_roll" type="revolute">
            <axis xyz="0 0 1"/>
            <parent link="base_link"/>
            <child link="fr_hip_roll_actuator"/>
            <origin rpy="0 1.5708 0" xyz="0.1415 -0.07 0"/>
            <limit effort="1000.0" lower="${-30 * deg2rad}" upper="${30 * deg2rad}" velocity="10"/>
            <dynamics damping="1.0" friction="1.0"/>
        </joint>

        <link name="fr_hip_roll_actuator">
            <inertial>
                <mass value="2e-06"/>
                <inertia ixx="1.1e-09" ixy="0" ixz="0" iyy="1.1e-09" iyz="0" izz="1.1e-09"/>
            </inertial>
        </link>

        <joint name="fr_hip_pitch" type="revolute">
            <axis xyz="0 1 0"/>
            <parent link="fr_hip_roll_actuator"/>
            <child link="fr_upper_link"/>
            <origin rpy="0 0 0" xyz="0 -0.0835 0.068"/>
            <limit effort="1000.0" lower="${-51 * deg2rad}" upper="${93 * deg2rad}" velocity="10"/>
            <dynamics damping="1.0" friction="1.0"/>
        </joint>

        <link name="fr_upper_link">
            <inertial>
                <origin rpy="0 0 0" xyz="0.11 0 0"/>
                <mass value="0.3"/>
                <inertia ixx="0.000066667" ixy="0" ixz="0" iyy="0.016166667" iyz="0" izz="0.016166667"/>
            </inertial>
            <visual>
                <origin rpy="0 0 0" xyz="0.11 0 0"/>
                <geometry>
                    <box size="0.22 0.04 0.04"/>
                </geometry>
                <material name="blue"/>
            </visual>
            <collision>
                <origin rpy="0 0 0" xyz="0.11 0 0"/>
                <geometry>
                    <box size="0.22 0.04 0.04"/>
                </geometry>
            </collision>
        </link>

        <joint name="fr_knee_pitch" type="revolute">
            <axis xyz="0 1 0"/>
            <parent link="fr_upper_link"/>
            <child link="fr_under_link"/>
            <origin rpy="0 0 0" xyz="0.22 0 0"/>
            <limit effort="1000.0" lower="${7 * deg2rad}" upper="${134 * deg2rad}" velocity="10"/>
            <dynamics damping="1.0" friction="1.0"/>
        </joint>

        <link name="fr_under_link">
            <inertial>
                <origin rpy="0 0 0" xyz="0.11 0 0"/>
                <mass value="0.3"/>
                <inertia ixx="0.000066667" ixy="0" ixz="0" iyy="0.016166667" iyz="0" izz="0.016166667"/>
            </inertial>
            <visual>
                <origin rpy="0 0 0" xyz="0.11 0 0"/>
                <geometry>
                    <box size="0.22 0.04 0.04"/>
                </geometry>
                <material name="blue"/>
            </visual>
            <collision>
                <origin rpy="0 0 0" xyz="0.11 0 0"/>
                <geometry>
                    <box size="0.22 0.04 0.04"/>
                </geometry>
            </collision>
        </link>

        <joint name="fr_foot" type="fixed">
            <axis xyz="0 1 0"/>
            <parent link="fr_under_link"/>
            <child link="fr_foot"/>
            <origin rpy="0 0 0" xyz="0.22 0 0"/>
        </joint>

        <link name="fr_foot">
            <inertial>
                <mass value="2e-06"/>
                <inertia ixx="1.1e-09" ixy="0" ixz="0" iyy="1.1e-09" iyz="0" izz="1.1e-09"/>
            </inertial>
            <visual>
                <origin rpy="0 0 0" xyz="0 0 0"/>
                <geometry>
                    <sphere radius="0.025"/>
                </geometry>
                <material name="white"/>
            </visual>
            <collision>
                <origin rpy="0 0 0" xyz="0 0 0"/>
                <geometry>
                    <sphere radius="0.025"/>
                </geometry>
            </collision>
        </link>

        <!-- Rear Left -->

        <joint name="rl_hip_roll" type="revolute">
            <axis xyz="0 0 1"/>
            <parent link="base_link"/>
            <child link="rl_hip_roll_actuator"/>
            <origin rpy="0 1.5708 0" xyz="-0.1415 0.07 0"/>
            <limit effort="1000.0" lower="${-30 * deg2rad}" upper="${30 * deg2rad}" velocity="10"/>
            <dynamics damping="1.0" friction="1.0"/>
        </joint>

        <link name="rl_hip_roll_actuator">
            <inertial>
                <mass value="2e-06"/>
                <inertia ixx="1.1e-09" ixy="0" ixz="0" iyy="1.1e-09" iyz="0" izz="1.1e-09"/>
            </inertial>
        </link>

        <joint name="rl_hip_pitch" type="revolute">
            <axis xyz="0 1 0"/>
            <parent link="rl_hip_roll_actuator"/>
            <child link="rl_upper_link"/>
            <origin rpy="0 0 0" xyz="0 0.0835 -0.068"/>
            <limit effort="1000.0" lower="${-51 * deg2rad}" upper="${93 * deg2rad}" velocity="10"/>
            <dynamics damping="1.0" friction="1.0"/>
        </joint>

        <link name="rl_upper_link">
            <inertial>
                <origin rpy="0 0 0" xyz="0.11 0 0"/>
                <mass value="0.3"/>
                <inertia ixx="0.000066667" ixy="0" ixz="0" iyy="0.016166667" iyz="0" izz="0.016166667"/>
            </inertial>
            <visual>
                <origin rpy="0 0 0" xyz="0.11 0 0"/>
                <geometry>
                    <box size="0.22 0.04 0.04"/>
                </geometry>
                <material name="blue"/>
            </visual>
            <collision>
                <origin rpy="0 0 0" xyz="0.11 0 0"/>
                <geometry>
                    <box size="0.22 0.04 0.04"/>
                </geometry>
            </collision>
        </link>

        <joint name="rl_knee_pitch" type="revolute">
            <axis xyz="0 1 0"/>
            <parent link="rl_upper_link"/>
            <child link="rl_under_link"/>
            <origin rpy="0 0 0" xyz="0.22 0 0"/>
            <limit effort="1000.0" lower="${7 * deg2rad}" upper="${134 * deg2rad}" velocity="10"/>
            <dynamics damping="1.0" friction="1.0"/>
        </joint>

        <link name="rl_under_link">
            <inertial>
                <origin rpy="0 0 0" xyz="0.11 0 0"/>
                <mass value="0.3"/>
                <inertia ixx="0.000066667" ixy="0" ixz="0" iyy="0.016166667" iyz="0" izz="0.016166667"/>
            </inertial>
            <visual>
                <origin rpy="0 0 0" xyz="0.11 0 0"/>
                <geometry>
                    <box size="0.22 0.04 0.04"/>
                </geometry>
                <material name="blue"/>
            </visual>
            <collision>
                <origin rpy="0 0 0" xyz="0.11 0 0"/>
                <geometry>
                    <box size="0.22 0.04 0.04"/>
                </geometry>
            </collision>
        </link>

        <joint name="rl_foot" type="fixed">
            <axis xyz="0 1 0"/>
            <parent link="rl_under_link"/>
            <child link="rl_foot"/>
            <origin rpy="0 0 0" xyz="0.22 0 0"/>
        </joint>

        <link name="rl_foot">
            <inertial>
                <mass value="2e-06"/>
                <inertia ixx="1.1e-09" ixy="0" ixz="0" iyy="1.1e-09" iyz="0" izz="1.1e-09"/>
            </inertial>
            <visual>
                <origin rpy="0 0 0" xyz="0 0 0"/>
                <geometry>
                    <sphere radius="0.025"/>
                </geometry>
                <material name="white"/>
            </visual>
            <collision>
                <origin rpy="0 0 0" xyz="0 0 0"/>
                <geometry>
                    <sphere radius="0.025"/>
                </geometry>
            </collision>
        </link>


        <!-- Rear Right -->

        <joint name="rr_hip_roll" type="revolute">
            <axis xyz="0 0 1"/>
            <parent link="base_link"/>
            <child link="rr_hip_roll_actuator"/>
            <origin rpy="0 1.5708 0" xyz="-0.1415 -0.07 0"/>
            <limit effort="1000.0" lower="${-30 * deg2rad}" upper="${30 * deg2rad}" velocity="10"/>
            <dynamics damping="1.0" friction="1.0"/>
        </joint>

        <link name="rr_hip_roll_actuator">
            <inertial>
                <mass value="2e-06"/>
                <inertia ixx="1.1e-09" ixy="0" ixz="0" iyy="1.1e-09" iyz="0" izz="1.1e-09"/>
            </inertial>
        </link>

        <joint name="rr_hip_pitch" type="revolute">
            <axis xyz="0 1 0"/>
            <parent link="rr_hip_roll_actuator"/>
            <child link="rr_upper_link"/>
            <origin rpy="0 0 0" xyz="0 -0.0835 -0.068"/>
            <limit effort="1000.0" lower="${-51 * deg2rad}" upper="${93 * deg2rad}" velocity="10"/>
            <dynamics damping="1.0" friction="1.0"/>
        </joint>

        <link name="rr_upper_link">
            <inertial>
                <origin rpy="0 0 0" xyz="0.11 0 0"/>
                <mass value="0.3"/>
                <inertia ixx="0.000066667" ixy="0" ixz="0" iyy="0.016166667" iyz="0" izz="0.016166667"/>
            </inertial>
            <visual>
                <origin rpy="0 0 0" xyz="0.11 0 0"/>
                <geometry>
                    <box size="0.22 0.04 0.04"/>
                </geometry>
                <material name="blue"/>
            </visual>
            <collision>
                <origin rpy="0 0 0" xyz="0.11 0 0"/>
                <geometry>
                    <box size="0.22 0.04 0.04"/>
                </geometry>
            </collision>
        </link>

        <joint name="rr_knee_pitch" type="revolute">
            <axis xyz="0 1 0"/>
            <parent link="rr_upper_link"/>
            <child link="rr_under_link"/>
            <origin rpy="0 0 0" xyz="0.22 0 0"/>
            <limit effort="1000.0" lower="${7 * deg2rad}" upper="${134 * deg2rad}" velocity="10"/>
            <dynamics damping="1.0" friction="1.0"/>
        </joint>

        <link name="rr_under_link">
            <inertial>
                <origin rpy="0 0 0" xyz="0.11 0 0"/>
                <mass value="0.3"/>
                <inertia ixx="0.000066667" ixy="0" ixz="0" iyy="0.016166667" iyz="0" izz="0.016166667"/>
            </inertial>
            <visual>
                <origin rpy="0 0 0" xyz="0.11 0 0"/>
                <geometry>
                    <box size="0.22 0.04 0.04"/>
                </geometry>
                <material name="blue"/>
            </visual>
            <collision>
                <origin rpy="0 0 0" xyz="0.11 0 0"/>
                <geometry>
                    <box size="0.22 0.04 0.04"/>
                </geometry>
            </collision>
        </link>

        <joint name="rr_foot" type="fixed">
            <axis xyz="0 1 0"/>
            <parent link="rr_under_link"/>
            <child link="rr_foot"/>
            <origin rpy="0 0 0" xyz="0.22 0 0"/>
        </joint>

        <link name="rr_foot">
            <inertial>
                <mass value="2e-06"/>
                <inertia ixx="1.1e-09" ixy="0" ixz="0" iyy="1.1e-09" iyz="0" izz="1.1e-09"/>
            </inertial>
            <visual>
                <origin rpy="0 0 0" xyz="0 0 0"/>
                <geometry>
                    <sphere radius="0.025"/>
                </geometry>
                <material name="white"/>
            </visual>
            <collision>
                <origin rpy="0 0 0" xyz="0 0 0"/>
                <geometry>
                    <sphere radius="0.025"/>
                </geometry>
            </collision>
        </link>

    </xacro:macro>

</robot>
