<?xml version="1.0" ?>
<robot name="standard_quadruped_robot">
  <material name="blue">
    <color rgba="0 0 1 1.000"/>
  </material>
  <material name="red">
    <color rgba="1 0 0 1.000"/>
  </material>
  <material name="silver">
    <color rgba="0.700 0.700 0.700 1.000"/>
  </material>

  <link name="base_link">
    <inertial>
      <origin rpy="0 0 0" xyz="0 0 0"/>
      <mass value="12"/>
      <inertia ixx="0.0683" ixy="0" ixz="0" iyy="0.1872" iyz="0" izz="0.2322"/>
    </inertial>
    <visual>
      <geometry>
        <box size="0.283 0.180 0.108"/>
      </geometry>
      <material name="red"/>
    </visual>
    <collision>
      <geometry>
        <box size="0.283 0.180 0.108"/>
      </geometry>
    </collision>
  </link>

  <!-- Front Left -->

  <joint name="fl_shoulder_yaw" type="continuous">
    <axis xyz="0 0 1"/>
    <parent link="base_link"/>
    <child link="fl_shoulder_yaw_actuator"/>
    <origin rpy="0 1.5708 0" xyz="0.1415 0.07 0"/>
  </joint>

  <link name="fl_shoulder_yaw_actuator"/>

  <joint name="fl_shoulder_pitch" type="continuous">
    <axis xyz="0 1 0"/>
    <parent link="fl_shoulder_yaw_actuator"/>
    <child link="fl_upper_link"/>
    <origin rpy="0 0 0" xyz="0 0.0835 0.068"/>
  </joint>

  <link name="fl_upper_link">
    <inertial>
      <origin rpy="0 0 0" xyz="0.11 0 0"/>
      <mass value="0.3"/>
      <inertia ixx="0.000066667" ixy="0" ixz="0" iyy="0.016166667" iyz="0" izz="0.016166667"/>
    </inertial>
    <visual>
      <origin rpy="0 0 0" xyz="0.11 0 0"/>
      <geometry>
        <box size="0.22 0.04 0.04"/>
      </geometry>
      <material name="blue"/>
    </visual>
    <collision>
      <origin rpy="0 0 0" xyz="0.11 0 0"/>
      <geometry>
        <box size="0.22 0.04 0.04"/>
      </geometry>
    </collision>
  </link>

  <joint name="fl_elbow_pitch" type="continuous">
    <axis xyz="0 1 0"/>
    <parent link="fl_upper_link"/>
    <child link="fl_under_link"/>
    <origin rpy="0 0 0" xyz="0.22 0 0"/>
  </joint>

  <link name="fl_under_link">
    <inertial>
      <origin rpy="0 0 0" xyz="0.11 0 0"/>
      <mass value="0.3"/>
      <inertia ixx="0.000066667" ixy="0" ixz="0" iyy="0.016166667" iyz="0" izz="0.016166667"/>
    </inertial>
    <visual>
      <origin rpy="0 0 0" xyz="0.11 0 0"/>
      <geometry>
        <box size="0.22 0.04 0.04"/>
      </geometry>
      <material name="blue"/>
    </visual>
    <collision>
      <origin rpy="0 0 0" xyz="0.11 0 0"/>
      <geometry>
        <box size="0.22 0.04 0.04"/>
      </geometry>
    </collision>
  </link>

  <joint name="fl_foot" type="fixed">
    <axis xyz="0 1 0"/>
    <parent link="fl_under_link"/>
    <child link="fl_foot"/>
    <origin rpy="0 0 0" xyz="0.22 0 0"/>
  </joint>

  <link name="fl_foot">
    <visual>
      <origin rpy="0 0 0" xyz="0 0 0"/>
      <geometry>
        <sphere radius="0.025"/>
      </geometry>
      <material name="silver"/>
    </visual>
    <collision>
      <origin rpy="0 0 0" xyz="0 0 0"/>
      <geometry>
        <sphere radius="0.025"/>
      </geometry>
    </collision>
  </link>

<!-- Front Right -->

  <joint name="fr_shoulder_yaw" type="continuous">
    <axis xyz="0 0 1"/>
    <parent link="base_link"/>
    <child link="fr_shoulder_yaw_actuator"/>
    <origin rpy="0 1.5708 0" xyz="0.1415 -0.07 0"/>
  </joint>

  <link name="fr_shoulder_yaw_actuator"/>

  <joint name="fr_shoulder_pitch" type="continuous">
    <axis xyz="0 1 0"/>
    <parent link="fr_shoulder_yaw_actuator"/>
    <child link="fr_upper_link"/>
    <origin rpy="0 0 0" xyz="0 -0.0835 0.068"/>
  </joint>

  <link name="fr_upper_link">
    <inertial>
      <origin rpy="0 0 0" xyz="0.11 0 0"/>
      <mass value="0.3"/>
      <inertia ixx="0.000066667" ixy="0" ixz="0" iyy="0.016166667" iyz="0" izz="0.016166667"/>
    </inertial>
    <visual>
      <origin rpy="0 0 0" xyz="0.11 0 0"/>
      <geometry>
        <box size="0.22 0.04 0.04"/>
      </geometry>
      <material name="blue"/>
    </visual>
    <collision>
      <origin rpy="0 0 0" xyz="0.11 0 0"/>
      <geometry>
        <box size="0.22 0.04 0.04"/>
      </geometry>
    </collision>
  </link>

  <joint name="fr_elbow_pitch" type="continuous">
    <axis xyz="0 1 0"/>
    <parent link="fr_upper_link"/>
    <child link="fr_under_link"/>
    <origin rpy="0 0 0" xyz="0.22 0 0"/>
  </joint>

  <link name="fr_under_link">
    <inertial>
      <origin rpy="0 0 0" xyz="0.11 0 0"/>
      <mass value="0.3"/>
      <inertia ixx="0.000066667" ixy="0" ixz="0" iyy="0.016166667" iyz="0" izz="0.016166667"/>
    </inertial>
    <visual>
      <origin rpy="0 0 0" xyz="0.11 0 0"/>
      <geometry>
        <box size="0.22 0.04 0.04"/>
      </geometry>
      <material name="blue"/>
    </visual>
    <collision>
      <origin rpy="0 0 0" xyz="0.11 0 0"/>
      <geometry>
        <box size="0.22 0.04 0.04"/>
      </geometry>
    </collision>
  </link>

  <joint name="fr_foot" type="fixed">
    <axis xyz="0 1 0"/>
    <parent link="fr_under_link"/>
    <child link="fr_foot"/>
    <origin rpy="0 0 0" xyz="0.22 0 0"/>
  </joint>

  <link name="fr_foot">
    <visual>
      <origin rpy="0 0 0" xyz="0 0 0"/>
      <geometry>
        <sphere radius="0.025"/>
      </geometry>
      <material name="silver"/>
    </visual>
    <collision>
      <origin rpy="0 0 0" xyz="0 0 0"/>
      <geometry>
        <sphere radius="0.025"/>
      </geometry>
    </collision>
  </link>

<!-- Rear Left -->

  <joint name="rl_shoulder_yaw" type="continuous">
    <axis xyz="0 0 1"/>
    <parent link="base_link"/>
    <child link="rl_shoulder_yaw_actuator"/>
    <origin rpy="0 1.5708 0" xyz="-0.1415 0.07 0"/>
  </joint>

  <link name="rl_shoulder_yaw_actuator"/>

  <joint name="rl_shoulder_pitch" type="continuous">
    <axis xyz="0 1 0"/>
    <parent link="rl_shoulder_yaw_actuator"/>
    <child link="rl_upper_link"/>
    <origin rpy="0 0 0" xyz="0 0.0835 -0.068"/>
  </joint>

  <link name="rl_upper_link">
    <inertial>
      <origin rpy="0 0 0" xyz="0.11 0 0"/>
      <mass value="0.3"/>
      <inertia ixx="0.000066667" ixy="0" ixz="0" iyy="0.016166667" iyz="0" izz="0.016166667"/>
    </inertial>
    <visual>
      <origin rpy="0 0 0" xyz="0.11 0 0"/>
      <geometry>
        <box size="0.22 0.04 0.04"/>
      </geometry>
      <material name="blue"/>
    </visual>
    <collision>
      <origin rpy="0 0 0" xyz="0.11 0 0"/>
      <geometry>
        <box size="0.22 0.04 0.04"/>
      </geometry>
    </collision>
  </link>

  <joint name="rl_elbow_pitch" type="continuous">
    <axis xyz="0 1 0"/>
    <parent link="rl_upper_link"/>
    <child link="rl_under_link"/>
    <origin rpy="0 0 0" xyz="0.22 0 0"/>
  </joint>

  <link name="rl_under_link">
    <inertial>
      <origin rpy="0 0 0" xyz="0.11 0 0"/>
      <mass value="0.3"/>
      <inertia ixx="0.000066667" ixy="0" ixz="0" iyy="0.016166667" iyz="0" izz="0.016166667"/>
    </inertial>
    <visual>
      <origin rpy="0 0 0" xyz="0.11 0 0"/>
      <geometry>
        <box size="0.22 0.04 0.04"/>
      </geometry>
      <material name="blue"/>
    </visual>
    <collision>
      <origin rpy="0 0 0" xyz="0.11 0 0"/>
      <geometry>
        <box size="0.22 0.04 0.04"/>
      </geometry>
    </collision>
  </link>

  <joint name="rl_foot" type="fixed">
    <axis xyz="0 1 0"/>
    <parent link="rl_under_link"/>
    <child link="rl_foot"/>
    <origin rpy="0 0 0" xyz="0.22 0 0"/>
  </joint>

  <link name="rl_foot">
    <visual>
      <origin rpy="0 0 0" xyz="0 0 0"/>
      <geometry>
        <sphere radius="0.025"/>
      </geometry>
      <material name="silver"/>
    </visual>
    <collision>
      <origin rpy="0 0 0" xyz="0 0 0"/>
      <geometry>
        <sphere radius="0.025"/>
      </geometry>
    </collision>
  </link>


  <!-- Rear Right -->

  <joint name="rr_shoulder_yaw" type="continuous">
    <axis xyz="0 0 1"/>
    <parent link="base_link"/>
    <child link="rr_shoulder_yaw_actuator"/>
    <origin rpy="0 1.5708 0" xyz="-0.1415 -0.07 0"/>
  </joint>

  <link name="rr_shoulder_yaw_actuator"/>

  <joint name="rr_shoulder_pitch" type="continuous">
    <axis xyz="0 1 0"/>
    <parent link="rr_shoulder_yaw_actuator"/>
    <child link="rr_upper_link"/>
    <origin rpy="0 0 0" xyz="0 -0.0835 -0.068"/>
  </joint>

  <link name="rr_upper_link">
    <inertial>
      <origin rpy="0 0 0" xyz="0.11 0 0"/>
      <mass value="0.3"/>
      <inertia ixx="0.000066667" ixy="0" ixz="0" iyy="0.016166667" iyz="0" izz="0.016166667"/>
    </inertial>
    <visual>
      <origin rpy="0 0 0" xyz="0.11 0 0"/>
      <geometry>
        <box size="0.22 0.04 0.04"/>
      </geometry>
      <material name="blue"/>
    </visual>
    <collision>
      <origin rpy="0 0 0" xyz="0.11 0 0"/>
      <geometry>
        <box size="0.22 0.04 0.04"/>
      </geometry>
    </collision>
  </link>

  <joint name="rr_elbow_pitch" type="continuous">
    <axis xyz="0 1 0"/>
    <parent link="rr_upper_link"/>
    <child link="rr_under_link"/>
    <origin rpy="0 0 0" xyz="0.22 0 0"/>
  </joint>

  <link name="rr_under_link">
    <inertial>
      <origin rpy="0 0 0" xyz="0.11 0 0"/>
      <mass value="0.3"/>
      <inertia ixx="0.000066667" ixy="0" ixz="0" iyy="0.016166667" iyz="0" izz="0.016166667"/>
    </inertial>
    <visual>
      <origin rpy="0 0 0" xyz="0.11 0 0"/>
      <geometry>
        <box size="0.22 0.04 0.04"/>
      </geometry>
      <material name="blue"/>
    </visual>
    <collision>
      <origin rpy="0 0 0" xyz="0.11 0 0"/>
      <geometry>
        <box size="0.22 0.04 0.04"/>
      </geometry>
    </collision>
  </link>

  <joint name="rr_foot" type="fixed">
    <axis xyz="0 1 0"/>
    <parent link="rr_under_link"/>
    <child link="rr_foot"/>
    <origin rpy="0 0 0" xyz="0.22 0 0"/>
  </joint>

  <link name="rr_foot">
    <visual>
      <origin rpy="0 0 0" xyz="0 0 0"/>
      <geometry>
        <sphere radius="0.025"/>
      </geometry>
      <material name="silver"/>
    </visual>
    <collision>
      <origin rpy="0 0 0" xyz="0 0 0"/>
      <geometry>
        <sphere radius="0.025"/>
      </geometry>
    </collision>
  </link>
</robot>
